<?xml version="1.0"?>
<robot xmlns:xacro="http://www.ros.org/wiki/xacro" name="rescue_robot">

  <!-- ======================== Properties ======================== -->
  <xacro:property name="base_length" value="0.60"/>
  <xacro:property name="base_width"  value="0.35"/>
  <xacro:property name="base_height" value="0.15"/>
  <xacro:property name="track_width"   value="0.4"/>
  <xacro:property name="wheel_radius"  value="0.062"/>
  <xacro:property name="wheel_width"   value="0.05"/>
  <xacro:property name="mesh_scale" value="1 1 1"/>

  <material name="silver"><color rgba="0.7 0.7 0.7 1"/></material>
  <material name="white"><color rgba="1 1 1 1"/></material>

  <!-- ======================== Base ======================== -->
  <link name="base_link">
    <visual><geometry><box size="${base_length} ${base_width} ${base_height}"/></geometry><material name="silver"/></visual>
  </link>

  <!-- Flippers (RPY based on Mesh Z-axis as length) -->
  <xacro:macro name="flipper" params="name x_offset y_offset flip_rpy">
    <link name="${name}">
      <visual><origin xyz="0 0 0" rpy="${flip_rpy}"/><geometry><mesh filename="package://bringup/meshes/flipper.STL" scale="${mesh_scale}"/></geometry><material name="white"/></visual>
    </link>
    <joint name="${name}_joint" type="revolute">
      <origin xyz="${x_offset} ${y_offset} ${-base_height/2}" rpy="0 0 0"/>
      <axis xyz="0 1 0"/><parent link="base_link"/><child link="${name}"/>
      <limit effort="5" lower="-3.14" upper="3.14" velocity="1.571"/>
    </joint>
  </xacro:macro>

  <!-- 正しい位置（左:+0.2, 右:-0.2）と向き -->
  <xacro:flipper name="flipper_fl" x_offset="0.3"  y_offset="0.2"   flip_rpy="${-pi/2} 0 ${-pi/2}"/>
  <xacro:flipper name="flipper_fr" x_offset="0.3"  y_offset="-0.2"  flip_rpy="${pi/2} 0 ${pi/2}"/>
  <xacro:flipper name="flipper_bl" x_offset="-0.3" y_offset="0.2"   flip_rpy="${pi/2} 0 ${-pi/2}"/>
  <xacro:flipper name="flipper_br" x_offset="-0.3" y_offset="-0.2"  flip_rpy="${-pi/2} 0 ${pi/2}"/>

  <!-- ======================== Arm (6DOF Full Restoration) ======================== -->
  <link name="arm_base_link">
    <visual><origin xyz="-0.08 -0.081 0" rpy="1.57 0 0"/><geometry><mesh filename="package://bringup/meshes/r_a_2019_2020_asm1.STL" scale="${mesh_scale}"/></geometry><material name="white"/></visual>
  </link>
  <joint name="arm_base_link_joint" type="fixed"><origin xyz="-0.2 0 ${base_height/2 + 0.06}"/><parent link="base_link"/><child link="arm_base_link"/></joint>

  <link name="arm1_link">
    <visual><origin xyz="0 0 0.004" rpy="1.57 0 0"/><geometry><mesh filename="package://bringup/meshes/r_a_2019_2020_asm2.STL" scale="${mesh_scale}"/></geometry></visual>
  </link>
  <joint name="arm_joint1" type="revolute"><origin xyz="0 0 0"/><axis xyz="0 0 1"/><parent link="arm_base_link"/><child link="arm1_link"/><limit effort="10" lower="-3.14" upper="3.14" velocity="1.571"/></joint>

  <link name="arm2_link">
    <visual><origin xyz="0 0 0" rpy="1.57 0 0"/><geometry><mesh filename="package://bringup/meshes/r_a_2019_2020_asm3.STL" scale="${mesh_scale}"/></geometry></visual>
  </link>
  <joint name="arm_joint2" type="revolute"><origin xyz="0 -0.048 0.078"/><axis xyz="0 1 0"/><parent link="arm1_link"/><child link="arm2_link"/><limit effort="20" lower="-3.14" upper="0" velocity="1.571"/></joint>

  <link name="arm3_link">
    <visual><origin xyz="0 0 0" rpy="1.57 0 0"/><geometry><mesh filename="package://bringup/meshes/r_a_2019_2020_asm4.STL" scale="${mesh_scale}"/></geometry></visual>
  </link>
  <joint name="arm_joint3" type="revolute"><origin xyz="0.45 0.007 0.084"/><axis xyz="0 1 0"/><parent link="arm2_link"/><child link="arm3_link"/><limit effort="20" lower="0" upper="3.14" velocity="1.571"/></joint>

  <link name="arm4_link">
    <visual><origin xyz="0 0 0" rpy="1.57 3.14 0"/><geometry><mesh filename="package://bringup/meshes/r_a_2019_2020_asm5.STL" scale="${mesh_scale}"/></geometry></visual>
  </link>
  <joint name="arm_joint4" type="revolute"><origin xyz="-0.5 0.012 0"/><axis xyz="0 1 0"/><parent link="arm3_link"/><child link="arm4_link"/><limit effort="10" lower="-4.71" upper="0" velocity="1.571"/></joint>

  <link name="arm5_link">
    <visual><origin xyz="0 0 0" rpy="1.57 3.14 0"/><geometry><mesh filename="package://bringup/meshes/r_a_2019_l_asm6.STL" scale="${mesh_scale}"/></geometry></visual>
  </link>
  <joint name="arm_joint5" type="revolute"><origin xyz="0.06525 0.028 0.029647"/><axis xyz="0 0 1"/><parent link="arm4_link"/><child link="arm5_link"/><limit effort="5" lower="-1.57" upper="1.57" velocity="1.571"/></joint>

  <link name="arm6_link">
    <visual><origin xyz="0 0 0" rpy="0 3.14 0"/><geometry><mesh filename="package://bringup/meshes/r_a_2019_l_asm7_ver2.STL" scale="${mesh_scale}"/></geometry></visual>
  </link>
  <joint name="arm_joint6" type="revolute"><origin xyz="0.07425 0 -0.03"/><axis xyz="1 0 0"/><parent link="arm5_link"/><child link="arm6_link"/><limit effort="5" lower="-3.14" upper="3.14" velocity="1.571"/></joint>

</robot>
